Workbook
Name IQ_CH: 110000
Name IQ_CQ: 5000
Name IQ_CY: 10000
Name IQ_DAILY: 500000
Name IQ_FH: 100000
Name IQ_FQ: 500
Name IQ_FY: 1000
Name IQ_LTM: 2000
Name IQ_MONTH: 15000
Name IQ_NTM: 6000
Name IQ_WEEK: 50000
Name IQ_YTD: 3000

Sheet RM Model Entitlement Codes
A1: productcode | B1: Description | C1: country | D1: continent | E1: peril | F1: RI Region | G1: RI Subregions | H1: Model SubType | I1: Model Type | J1: Bundle Countries | K1: Bundle Region | L1: Bundle Subregion
A2: ALM-EQ-ARG | B2: ALM Earthquake Argentina | C2: Argentina | D2: South America | E2: Earthquake | G2: AR | H2: Base | I2: ALM | K2: Latin America | L2: South America | N2: Latin America
A3: ALM-EQ-AUS | B3: ALM Earthquake Australia | C3: Australia | D3: Oceania/Australasia | E3: Earthquake | G3: AU | H3: Base | I3: ALM | K3: Australia New Zealand | L3: Australia | N3: Australia + New Zealand
A4: ALM-EQ-AUT | B4: ALM Earthquake Austria | C4: Austria | D4: Europe | E4: Earthquake | G4: AT | H4: Base | I4: ALM | K4: Europe | L4: Austria | N4: Europe
A5: ALM-EQ-BEL | B5: ALM Earthquake Belgium | C5: Belgium | D5: Europe | E5: Earthquake | G5: BE | H5: Base | I5: ALM | K5: Europe | L5: Benelux | N5: Japan
A6: ALM-EQ-BGR | B6: ALM Earthquake Bulgaria | C6: Bulgaria | D6: Europe | E6: Earthquake | G6: BG | H6: Base | I6: ALM | K6: Europe | N6: Asia excluding Japan
A7: ALM-EQ-BLZ | B7: ALM Earthquake Belize | C7: Belize | D7: South America | E7: Earthquake | G7: BZ | H7: Base | I7: ALM | K7: Latin America | L7: Central America
A8: ALM-EQ-BOL | B8: ALM Earthquake Bolivia | C8: Bolivia | D8: South America | E8: Earthquake | G8: BO | H8: Base | I8: ALM | K8: Latin America | L8: South America
A9: ALM-EQ-BRA | B9: ALM Earthquake Brazil | C9: Brazil | D9: South America | E9: Earthquake | G9: BR | H9: Base | I9: ALM | K9: Latin America | L9: South America
A10: ALM-EQ-CAN | B10: ALM Earthquake Canada | C10: Canada | D10: North America | E10: Earthquake | G10: CA | H10: Base | I10: ALM | K10: North America | L10: Canada
A11: ALM-EQ-CAR | B11: ALM Earthquake Caribbean | C11: Caribbean | D11: North America | E11: Earthquake | G11: CB,FC | H11: Base | I11: ALM | J11: Anguillaa,Antigua and Barbuda,Barbados,British Virgin Islands,Cayman Islands,Dominica,Dominican Republic,Grenada,Guadaloupe,Haiti,Jamaica,Martinique,Montserrat,Netherlands Antilles,Puerto Rico,St. Kitts and Nevis,St. Lucia,St. Martin,St. Vincent and the Grenadines,Trinidad and Tobago,Turks and Caicos,U.S. Virgin Islands | K11: Latin America | L11: Caribbean
A12: ALM-EQ-CHE | B12: ALM Earthquake Switzerland | C12: Switzerland | D12: Europe | E12: Earthquake | G12: CH | H12: Base | I12: ALM | K12: Europe | L12: Switzerland
A13: ALM-EQ-CHL | B13: ALM Earthquake Chile | C13: Chile | D13: South America | E13: Earthquake | G13: CL | H13: Base | I13: ALM | K13: Latin America | L13: South America
A14: ALM-EQ-CHN | B14: ALM Earthquake China | C14: China | D14: Asia | E14: Earthquake | G14: CN,HK | H14: Base | I14: ALM | K14: Asia
A15: ALM-EQ-COL | B15: ALM Earthquake Colombia | C15: Colombia | D15: South America | E15: Earthquake | G15: CO | H15: Base | I15: ALM | K15: Latin America | L15: South America
A16: ALM-EQ-CRI | B16: ALM Earthquake Costa Rica | C16: Costa Rica | D16: North America | E16: Earthquake | G16: CR | H16: Base | I16: ALM | K16: Latin America | L16: Central America
A17: ALM-EQ-DEU | B17: ALM Earthquake Germany | C17: Germany | D17: Europe | E17: Earthquake | G17: DE | H17: Base | I17: ALM | K17: Europe | L17: Germany
A18: ALM-EQ-ECU | B18: ALM Earthquake Ecuador | C18: Ecuador | D18: South America | E18: Earthquake | G18: EC | H18: Base | I18: ALM | K18: Latin America | L18: Central America
A19: ALM-EQ-ESP | B19: ALM Earthquake Spain | C19: Spain | D19: Europe | E19: Earthquake | G19: ES | H19: Base | I19: ALM | K19: Europe
A20: ALM-EQ-EUR | B20: ALM Earthquake Europe Bundle | C20: Europe | D20: Europe | E20: Earthquake | G20: EU,AT,BE,BG,CH,DE,ES,FR,GB,GR,HU,IE,IT,LI,LU,NL,PT,RO,SI,TR,AD | H20: Base | I20: ALM | J20: Austria,Belgium,Bulgaria,Switzerland,Germany,Spain,France,Greece,Hungary,Ireland,Italy,Liechtenstein,Luxembourg,Netherlands,Portugal,Romania,Slovenia,Turkey,United Kingdom | K20: Europe
A21: ALM-EQ-EUR-21 | B21: ALM Earthquake Europe 21 Country Bundle | C21: Europe | D21: Europe | E21: Earthquake | G21: EU,AT,BE,BG,CH,DE,ES,FR,GB,GR,HU,IE,IL,IT,LI,LU,NL,PT,RO,SI,TR,AD | H21: Base | I21: ALM | J21: Austria,Belgium,Bulgaria,Switzerland,Germany,Spain,France,Greece,Hungary,Ireland,Israel,Italy,Liechtenstein,Luxembourg,Netherlands,Portugal,Romania,Slovenia,Turkey,United Kingdom | K21: Europe
A22: ALM-EQ-FRA | B22: ALM Earthquake France | C22: France | D22: Europe | E22: Earthquake | G22: FR | H22: Base | I22: ALM | K22: Europe | L22: France
A23: ALM-EQ-GRC | B23: ALM Earthquake Greece | C23: Greece | D23: Europe | E23: Earthquake | G23: GR | H23: Base | I23: ALM | K23: Europe
A24: ALM-EQ-GTM | B24: ALM Earthquake Guatemala | C24: Guatemala | D24: North America | E24: Earthquake | G24: GT | H24: Base | I24: ALM | K24: Latin America | L24: Central America
A25: ALM-EQ-HKG | B25: ALM Earthquake Hong Kong | C25: Hong Kong | D25: Asia | E25: Earthquake | G25: HK | H25: Base | I25: ALM | K25: Asia
A26: ALM-EQ-HND | B26: ALM Earthquake Honduras | C26: Honduras | D26: North America | E26: Earthquake | G26: HN | H26: Base | I26: ALM | K26: Latin America | L26: Central America
A27: ALM-EQ-HUN | B27: ALM Earthquake Hungary | C27: Hungary | D27: Europe | E27: Earthquake | G27: HU | H27: Base | I27: ALM | K27: Europe
A28: ALM-EQ-IDN | B28: ALM Earthquake Indonesia | C28: Indonesia | D28: Asia | E28: Earthquake | G28: ID | H28: Base | I28: ALM | K28: Asia | L28: Southeast Asia
A29: ALM-EQ-IND | B29: ALM Earthquake India | C29: India | D29: Asia | E29: Earthquake | G29: IN | H29: Base | I29: ALM | K29: Asia | L29: India
A30: ALM-EQ-IRL | B30: ALM Earthquake Ireland | C30: Ireland | D30: Europe | E30: Earthquake | G30: IE | H30: Base | I30: ALM | K30: Europe
A31: ALM-EQ-ISR | B31: ALM Earthquake Israel | C31: Israel | D31: Europe | E31: Earthquake | G31: IL | H31: Base | I31: ALM | K31: Europe
A32: ALM-EQ-ITA | B32: ALM Earthquake Italy | C32: Italy | D32: Europe | E32: Earthquake | G32: IT | H32: Base | I32: ALM | K32: Europe | L32: Italy
A33: ALM-EQ-JPN | B33: ALM Earthquake Japan | C33: Japan | D33: Asia | E33: Earthquake | G33: JP | H33: Base | I33: ALM | K33: Asia | L33: Japan
A34: ALM-EQ-KOR | B34: ALM Earthquake South Korea | C34: South Korea | D34: Asia | E34: Earthquake | G34: KR | H34: Base | I34: ALM | K34: Asia | L34: South Korea
A35: ALM-EQ-LAM | B35: ALM Earthquake Central and South America Bundle | C35: Central and South America | D35: South America | E35: Earthquake | G35: AR,BO,BR,BZ,CL,CO,CR,GT,HN,NI,PA,PE,SV,EC,VE | H35: Base | I35: ALM | J35: Belize,Costa Rica,El Salvador,Guatemala,Honduras,Nicaragua,Panama,Argentina,Bolivia,Brazil,Chile,Colombia,Equador,Peru,Venezuela | K35: Latin America
A36: ALM-EQ-LIE | B36: ALM Earthquake Liechtenstein | C36: Liechtenstein | D36: Europe | E36: Earthquake | G36: LI | H36: Base | I36: ALM | K36: Europe | L36: Switzerland
A37: ALM-EQ-LUX | B37: ALM Earthquake Luxembourg | C37: Luxembourg | D37: Europe | E37: Earthquake | G37: LU | H37: Base | I37: ALM | K37: Europe | L37: Benelux
A38: ALM-EQ-MEX | B38: ALM Earthquake Mexico | C38: Mexico | D38: North America | E38: Earthquake | G38: MX | H38: Base | I38: ALM | K38: Latin America | L38: Mexico
A39: ALM-EQ-NIC | B39: ALM Earthquake Nicaragua | C39: Nicaragua | D39: North America | E39: Earthquake | G39: NI | H39: Base | I39: ALM | K39: Latin America | L39: Central America
A40: ALM-EQ-NLD | B40: ALM Earthquake Netherlands | C40: Netherlands | D40: Europe | E40: Earthquake | G40: NL | H40: Base | I40: ALM | K40: Europe | L40: Benelux
...

Sheet RM Data Entitlement Codes
A1: productcode | B1: productname | C1: Data API Name | D1: RI Region | E1: RI Subregion | F1: Peril | G1: Data Type | H1: Comment | I1: Bundle Region | J1: Bundle Subregion
A2: DATA-FLOOD | B2: Enhanced FEMA Flood Data | C2: us_fema_firm | D2: North America | E2: US | F2: Flood | G2: Hazard | J2: United States
A3: MAP-FL-US | B3: U.S. Flood Hazard Depths | C3: us_fl_depth | D3: North America | E3: US | F3: Flood | G3: Hazard | J3: United States
A4: DATAMAP-US-FL | B4: Enhanced FEMA Flood Data & U.S. Flood Hazard Depths Bundle | C4: us_fema_firm, us_fl_depth | D4: North America | E4: US | F4: Flood | G4: Hazard | H4: Entitled via two API names | J4: United States
A5: DATA-WF-SUPP-USA | B5: U.S. Wildfire Supplemental Hazard | C5: us_wf_supplemental_hazard | D5: North America | E5: US | F5: Wildfire | G5: Hazard | J5: United States
A6: DATA-WFRSC-USA | B6: U.S. Wildfire RiskScore | C6: us_wf_risk_score | D6: North America | E6: US | F6: Wildfire | G6: RiskScore | J6: United States
A7: DATA-DTF | B7: U.S. Earthquake Distance to Fault | C7: us_distance_to_fault | D7: North America | E7: US | F7: Earthquake | G7: Hazard | J7: United States
A8: DATA-MMI | B8: U.S. Earthquake MMI | C8: us_mmi | D8: North America | E8: US | F8: Earthquake | G8: Hazard | J8: United States
A9: MAP-MMI-NZL | B9: NZ Earthquake MMI | C9: nz_mmi | D9: Oceania/Australasia | E9: NZ | F9: Earthquake | G9: Hazard
A10: DATA-SUB | B10: U.S. Subsidence | C10: us_subsidence | D10: North America | E10: US | F10: Other | G10: Hazard | J10: United States
A11: DATA-WPZ | B11: U.S. Windpool Zones | C11: us_ws_windpool_zone | D11: North America | E11: US | F11: Windstorm | G11: Hazard | J11: United States
A12: DATA-HURSC | B12: U.S. Hurricane Risk Score | C12: us_ws_risk_score | D12: North America | E12: US | F12: Windstorm | G12: RiskScore | J12: United States
A13: DATA-EQRSC | B13: U.S. Earthquake Risk Score | C13: us_eq_risk_score | D13: North America | E13: US | F13: Earthquake | G13: RiskScore | J13: United States
A14: GFM-FL-AFR | B14: Global Flood Maps: Africa Bundle | C14: global_fl_depth | D14: Global | E14: BI, KM, NE, DZ, AO, BJ, BF, CF, CM, DJ, GQ, CD, BW, TD, GA, EG, ER, SZ, ET, MG, MW, LS, KE, LR, GH, GN, CI, NG, SN, LY, CG, SL, MR, ML, NA, TZ, RW, MZ, GW, YT, MA, RE, ST, SO, ZA, SS, SD, GM, TG, TN, UG, ZM, ZW, MU, CV, SC | F14: Flood | G14: Hazard
A15: GFM-FL-AMER | B15: Global Flood Maps: Americas Bundle | C15: global_fl_depth | D15: Global | E15: US, CA, CB, PM, AR, BO, BR, CL, CO, EC, FK, GF, GY, PY, PE, SR, UY, VE, BZ, CR, SV, GT, HN, MX, NI, PA | F15: Flood | G15: Hazard
A16: GFM-FL-APAC | B16: Global Flood Maps: Asia Pacific Bundle | C16: global_fl_depth | D16: Global | E16: AF, AM, AZ, BD, BT, BN, KH, CN, TL, GE, HK, IN, ID, JP, KZ, KG, LA, MY, MN, MM, NP, KP, PK, PH, SG, KR, LK, TW, TJ, TH, TM, UZ, VN, AU, NZ, AS, CX, CK, FM, FJ, PF, GU, KI, NR, NC, GU, PW, PG, WS, SB, TO, VU, NU, WF | F16: Flood | G16: Hazard
A17: GFM-FL-CAR | B17: Global Flood Maps: Caribbean Bundle | C17: global_fl_depth | D17: Global | E17: CB | F17: Flood | G17: Hazard
A18: GFM-FL-EMEA | B18: Global Flood Maps: Europe, Middle East and Africa Bundle | C18: global_fl_depth | D18: Global | E18: AL, AD, AT, BY, BE, BA, BG, HR, CZ, DK, EE, FI, FR, DE, GR, GB, HU, IS, IE, IT, GB, CS, LV, LI, LT, LU, MT, MD, CS, NL, NO, PL, PT, MK, RO, SK, SI, ES, SE, CH, UA, RU, FO, BH, CY, IR, IQ, IL, JO, KW, LB, OM, IL, QA, SA, SY, TR, AE, YE, BI, KM, NE, DZ, AO, BJ, BF, CF, CM, DJ, GQ, CD, BW, TD, GA, EG, ER, SZ, ET, MG, MW, LS, KE, LR, GH, GN, CI, NG, SN, LY, CG, SL, MR, ML, NA, TZ, RW, MZ, GW, YT, MA, RE, ST, SO, ZA, SS, SD, GM, TG, TN, UG, ZM, ZW, MU, CV, SC | F18: Flood | G18: Hazard
A19: GFM-FL-GBL | B19: Global Flood Maps: Global Bundle | C19: global_fl_depth | D19: Global | E19: Global | F19: Flood | G19: Hazard
A20: GFM-FL-LAM | B20: Global Flood Maps: Latin America Bundle | C20: global_fl_depth | D20: Global | E20: AR, BO, BR, CL, CO, EC, FK, GF, GY, PY, PE, SR, UY, VE, BZ, CR, SV, GT, HN, MX, NI, PA | F20: Flood | G20: Hazard
A21: GFM-FL-ME | B21: Global Flood Maps: Middle East Bundle | C21: global_fl_depth | D21: Global | E21: BH, CY, IR, IQ, IL, JO, KW, LB, OM, IL, QA, SA, SY, TR, AE, YE | F21: Flood | G21: Hazard
A22: GFM-FL-PACISLANDS | B22: Global Flood Maps: Pacific Islands Bundle | C22: global_fl_depth | D22: Global | E22: AS, CX, CK, FM, FJ, PF, GU, KI, NR, NC, GU, PW, PG, WS, SB, TO, VU, NU, WF | F22: Flood | G22: Hazard
A23: DATA-WTRSC-USA | B23: U.S. Winterstorm Risk Score | C23: us_wt_risk_score | D23: North America | E23: US | F23: Winterstorm | G23: RiskScore | J23: United States
A24: DATA-FIRESTATION-USA | B24: U.S. Distance to Fire Station | C24: us_distance_to_fire_station | D24: North America | E24: US | F24: Other | G24: Hazard | J24: United States
A25: DATA-FLRSC-USA | B25: U.S. Flood Risk Score | C25: us_fl_risk_score | D25: North America | E25: US | F25: Flood | G25: RiskScore | J25: United States
A26: DATA-FLRSC-EUR | B26: Europe Flood Risk Score | C26: eu_fl_risk_score | D26: Europe | E26: AT, BE, CZ, FR, DE, HU, IT, IE, LU, LI, FR, PL, SK, CH, GB | F26: Flood | G26: RiskScore | I26: Europe
A27: DATA-HURSC-EUR | B27: Europe Windstorm Risk Score | C27: eu_ws_risk_score | D27: Europe | E27: AT, BE, CZ, DK, FR, DE, IE, LU, NL, NO, PL, SK, SE, CH, GB | F27: Windstorm | G27: RiskScore | I27: Europe
A28: DATA-EQRSC-EUR | B28: Europe Earthquake Risk Score | C28: eu_eq_risk_score | D28: Europe | E28: AD, AT, BE, BG, FR, DE, GR, HU, IE, IT, LI, LU, NL, PT, RO, SI, ES, CH, TR, GB | F28: Earthquake | G28: RiskScore | I28: Europe
A29: DATA-HURSC-AUS | B29: Australia Cyclone Risk Score | C29: au_ws_risk_score | D29: Oceania/Australasia | E29: AU | F29: Windstorm | G29: RiskScore
A30: DATA-EQRSC-AUS | B30: Australia Earthquake Risk Score | C30: au_eq_risk_score | D30: Oceania/Australasia | E30: AU | F30: Earthquake | G30: RiskScore
A31: DATA-EQRSC-CAN | B31: Canada Earthquake Risk Score | C31: ca_eq_risk_score | D31: North America | E31: CA | F31: Earthquake | G31: RiskScore
A32: DATA-WTRSC-CAN | B32: Canada Winterstorm Risk Score | C32: ca_wt_risk_score | D32: North America | E32: CA | F32: Winterstorm | G32: RiskScore
A33: DATA-FLDPTH-EUR | B33: Europe Flood Hazard Depths | C33: eu_fl_depth | D33: Europe | E33: AT, BE, CZ, FR, DE, HU, IT, IE, LU, LI, FR, PL, SK, CH, GB | F33: Flood | G33: Hazard | I33: Europe
A34: DATA-EQRSC-CAR | B34: Caribbean Earthquake Risk Score | C34: cb_eq_risk_score | D34: North America | E34: CB | F34: Earthquake | G34: RiskScore
A35: DATA-HURSC-CAR | B35: Caribbean Hurricane Risk Score | C35: cb_ws_risk_score | D35: North America | E35: CB | F35: Windstorm | G35: RiskScore
A36: MAP-FL-NZL | B36: New Zealand Flood Hazard Depths | C36: nz_fl_depth | D36: Oceania/Australasia | E36: NZ | F36: Flood | G36: Hazard
A37: MAP-MMI-CAN | B37: Canada Earthquake MMI | C37: ca_mmi | D37: North America | E37: CA | F37: Earthquake | G37: Hazard
A38: MMI-EQ-CHN | B38: China Earthquake MMI | D38: Asia | E38: CN | F38: Earthquake | G38: Hazard | H38: not yet released
A39: MAP-MMI-EUR | B39: Europe Earthquake MMI | C39: eu_mmi | D39: Europe | E39: AD, AT, BE, BG, FR, DE, GR, HU, IE, IT, LI, LU, NL, PT, RO, SI, ES, CH, TR, GB | F39: Earthquake | G39: Hazard | I39: Europe
A40: DATA-WF-SUPP-CAN | B40: Canada Wildfire Supplemental Hazard | C40: ca_wf_supplemental_hazard | D40: North America | E40: CA | F40: Wildfire | G40: Hazard | H40: not yet released
...

Sheet RI SaaS Codes
B1: Product Name | C1: Group | D1: EntitlementActivated
A2: HD-FL-US | B2: HD Inland Flood U.S. | C2: HD | D2: =NOT(ISERROR(MATCH(A2,'RM Model Entitlement Codes'!$A$2:$A$399,0))) -> FALSE
A3: HD-IFM-FL-US | B3: HD IFM Flood U.S. | C3: HD | D3: =NOT(ISERROR(MATCH(A3,'RM Model Entitlement Codes'!$A$2:$A$399,0))) -> FALSE
A4: HD-WF-CAN | B4: Canada Wildfire HD Model | C4: HD | D4: =NOT(ISERROR(MATCH(A4,'RM Model Entitlement Codes'!$A$2:$A$399,0))) -> FALSE
A5: HD-WF-US | B5: U.S. Wildfire HD Model | C5: HD | D5: =NOT(ISERROR(MATCH(A5,'RM Model Entitlement Codes'!$A$2:$A$399,0))) -> FALSE
A6: HD-WS-JPN | B6: HD Typhoon Japan | C6: HD | D6: =NOT(ISERROR(MATCH(A6,'RM Model Entitlement Codes'!$A$2:$A$399,0))) -> FALSE
A7: HD-FL-AUT | B7: HD Flood Austria | C7: HD | D7: =NOT(ISERROR(MATCH(A7,'RM Model Entitlement Codes'!$A$2:$A$399,0))) -> TRUE
A8: HD-FL-BEL | B8: HD Flood Belgium | C8: HD | D8: =NOT(ISERROR(MATCH(A8,'RM Model Entitlement Codes'!$A$2:$A$399,0))) -> TRUE
A9: HD-FL-CHE | B9: HD Flood Switzerland | C9: HD | D9: =NOT(ISERROR(MATCH(A9,'RM Model Entitlement Codes'!$A$2:$A$399,0))) -> FALSE
A10: HD-FL-CZE | B10: HD Flood Czech Republic | C10: HD | D10: =NOT(ISERROR(MATCH(A10,'RM Model Entitlement Codes'!$A$2:$A$399,0))) -> FALSE
A11: HD-FL-DEU | B11: HD Flood Germany | C11: HD | D11: =NOT(ISERROR(MATCH(A11,'RM Model Entitlement Codes'!$A$2:$A$399,0))) -> FALSE
A12: HD-FL-EUR-ALL | B12: HD Flood Europe 15 Country Bundle | C12: HD | D12: =NOT(ISERROR(MATCH(A12,'RM Model Entitlement Codes'!$A$2:$A$399,0))) -> FALSE
A13: HD-FL-FRA | B13: HD Flood France | C13: HD | D13: =NOT(ISERROR(MATCH(A13,'RM Model Entitlement Codes'!$A$2:$A$399,0))) -> FALSE
... A39: HD-IFM-WS-JPN | B39: HD IFM Typhoon Japan | C39: HD | D39: =NOT(ISERROR(MATCH(A39,'RM Model Entitlement Codes'!$A$2:$A$399,0))) -> FALSE
A40: DLM-WS-PAN | B40: Model | C40: DLM | D40: =NOT(ISERROR(MATCH(A40,'RM Model Entitlement Codes'!$A$2:$A$302,0))) -> TRUE
A41: DLM-WS-NIC | B41: Model | C41: DLM | D41: =NOT(ISERROR(MATCH(A41,'RM Model Entitlement Codes'!$A$2:$A$302,0))) -> TRUE
A42: DLM-WS-HND | B42: Model | C42: DLM | D42: =NOT(ISERROR(MATCH(A42,'RM Model Entitlement Codes'!$A$2:$A$302,0))) -> TRUE
A43: DLM-WS-GTM | B43: Model | C43: DLM | D43: =NOT(ISERROR(MATCH(A43,'RM Model Entitlement Codes'!$A$2:$A$302,0))) -> TRUE
A44: DLM-WS-CRI | B44: Model | C44: DLM | D44: =NOT(ISERROR(MATCH(A44,'RM Model Entitlement Codes'!$A$2:$A$302,0))) -> TRUE
A45: DLM-WS-BLZ | B45: Model | C45: DLM | D45: =NOT(ISERROR(MATCH(A45,'RM Model Entitlement Codes'!$A$2:$A$302,0))) -> TRUE
A46: DLM-WS-CAM | B46: Model | C46: DLM | D46: =NOT(ISERROR(MATCH(A46,'RM Model Entitlement Codes'!$A$2:$A$302,0))) -> TRUE
A47: DLM-SCS-US | B47: Model | C47: DLM | D47: =NOT(ISERROR(MATCH(A47,'RM Model Entitlement Codes'!$A$2:$A$302,0))) -> TRUE
A48: DLM-SCS-CAN | B48: Model | C48: DLM | D48: =NOT(ISERROR(MATCH(A48,'RM Model Entitlement Codes'!$A$2:$A$302,0))) -> TRUE
A49: DLM-WS-CAR | B49: Model | C49: DLM | D49: =NOT(ISERROR(MATCH(A49,'RM Model Entitlement Codes'!$A$2:$A$302,0))) -> TRUE
A50: DLM-WSOP-US | B50: Model | C50: DLM | D50: =NOT(ISERROR(MATCH(A50,'RM Model Entitlement Codes'!$A$2:$A$302,0))) -> TRUE
A51: DLM-WS-US | B51: Model | C51: DLM | D51: =NOT(ISERROR(MATCH(A51,'RM Model Entitlement Codes'!$A$2:$A$302,0))) -> TRUE
... A439: IFM-EQ-VEN | B439: IFM Earthquake Venezuela | C439: IFM | D439: =NOT(ISERROR(MATCH(A439,'RM Model Entitlement Codes'!$A$2:$A$302,0))) -> FALSE
A440: DLM-WSBR-CAN | B440: Model | C440: Builder's Risk | D440: =NOT(ISERROR(MATCH(A440,'RM Model Entitlement Codes'!$A$2:$A$399,0))) -> TRUE
A441: DLM-WSBR-MEX | B441: Model | C441: Builder's Risk | D441: =NOT(ISERROR(MATCH(A441,'RM Model Entitlement Codes'!$A$2:$A$399,0))) -> TRUE
A442: DLM-WSBR-US | B442: Model | C442: Builder's Risk | D442: =NOT(ISERROR(MATCH(A442,'RM Model Entitlement Codes'!$A$2:$A$399,0))) -> TRUE
A443: DLM-FLBR-IND | B443: Model | C443: Builder's Risk | D443: =NOT(ISERROR(MATCH(A443,'RM Model Entitlement Codes'!$A$2:$A$399,0))) -> TRUE
A444: HD-FLBR-US | B444: DLM Flood Builders Risk United States | C444: Builder's Risk | D444: =NOT(ISERROR(MATCH(A444,'RM Model Entitlement Codes'!$A$2:$A$399,0))) -> FALSE
A445: DLM-WSBR-KOR | B445: Model | C445: Builder's Risk | D445: =NOT(ISERROR(MATCH(A445,'RM Model Entitlement Codes'!$A$2:$A$399,0))) -> TRUE
A446: DLM-WSBR-TWN | B446: Model | C446: Builder's Risk | D446: =NOT(ISERROR(MATCH(A446,'RM Model Entitlement Codes'!$A$2:$A$399,0))) -> TRUE
A447: DLM-WSBR-AUS | B447: Model | C447: Builder's Risk | D447: =NOT(ISERROR(MATCH(A447,'RM Model Entitlement Codes'!$A$2:$A$399,0))) -> TRUE
A448: DLM-WSBR-PHL | B448: Model | C448: Builder's Risk | D448: =NOT(ISERROR(MATCH(A448,'RM Model Entitlement Codes'!$A$2:$A$399,0))) -> FALSE
A449: DLM-WSBR-CHN | B449: Model | C449: Builder's Risk | D449: =NOT(ISERROR(MATCH(A449,'RM Model Entitlement Codes'!$A$2:$A$399,0))) -> TRUE
A450: HD-WSBR-JPN | B450: HD Windstorm Builders Risk Japan | C450: Builder's Risk | D450: =NOT(ISERROR(MATCH(A450,'RM Model Entitlement Codes'!$A$2:$A$399,0))) -> FALSE
A451: DLM-EQBR-KOR | B451: Model | C451: Builder's Risk | D451: =NOT(ISERROR(MATCH(A451,'RM Model Entitlement Codes'!$A$2:$A$399,0))) -> TRUE
... A467: ALM-EQ-ARG | B467: ALM Earthquake Argentina | C467: ALM | D467: =NOT(ISERROR(MATCH(A467,'RM Model Entitlement Codes'!$A$2:$A$399,0))) -> TRUE
...

Sheet OME
A1: productcode | B1: productname | C1: peril | D1: RI Region | E1: RI Subregions | F1: Model SubType | G1: Model Type
A2: NASDAQ-FATHOM-USFL | B2: Nasdaq Fathom Flood United States | C2: Flood | D2: United States | E2: United States | F2: Fathom | G2: Nasdaq
A3: NASDAQ-JBA-ZZFL | B3: Nasdaq JBA Flood Global | C3: Flood | D3: Global | E3: Global | F3: JBA | G3: Nasdaq
A4: NASDAQ-ARA-USWS | B4: Nasdaq ARA Windstorm United States | C4: Windstorm | D4: United States | E4: United States | F4: ARA | G4: Nasdaq
A5: NASDAQ-IMPACT-CAFL | B5: Nasdaq Impact Forecasting Flood Canada | C5: Flood | D5: Canada | E5: Canada | F5: Impact Forecasting | G5: Nasdaq
A6: NASDAQ-IMPACT-USTR | B6: Nasdaq Impact Forecasting Terrorism United States | C6: Terrorism | D6: United States | E6: United States | F6: Impact Forecasting | G6: Nasdaq
A7: NASDAQ-IMPACT-USWC | B7: Nasdaq Impact Forecasting Worker's Compensation United States | C7: Workers Comp | D7: United States | E7: United States | F7: Impact Forecasting | G7: Nasdaq
A8: NASDAQ-ARA-NAWS | B8: Nasdaq ARA Windstorm North Atlantic | C8: Windstorm | D8: North Atlantic | E8: North Atlantic | F8: ARA | G8: Nasdaq
A9: NASDAQ-FATHOM-ZZFL | B9: Nasdaq Fathom Flood Global | C9: Flood | D9: Global | E9: Global | F9: Fathom | G9: Nasdaq
A10: NASDAQ-IMPACT-EUSCS | B10: Nasdaq Impact Forecasting Severe Convective Storm Europe | C10: Severe Convective Storm | D10: Europe | E10: Europe | F10: Impact Forecasting | G10: Nasdaq
A11: NASDAQ-IMPACT-CHFL | B11: Nasdaq Impact Forecasting Flood Switzerland | C11: Flood | D11: Switzerland | E11: Switzerland | F11: Impact Forecasting | G11: Nasdaq
A12: NASDAQ-IMPACT-ATFL | B12: Nasdaq Impact Forecasting Flood Austria | C12: Flood | D12: Austria | E12: Austria | F12: Impact Forecasting | G12: Nasdaq
A13: NASDAQ-JBA-UKFL | B13: Nasdaq JBA Flood United Kingdom | C13: Flood | D13: United Kingdom | E13: United Kingdom | F13: JBA | G13: Nasdaq

Sheet ProductModifier
A1: Vulnerability Curve Name | B1: ProductCode | C1: ProductModifier | D1: Description | E1: Quota Scale factor | F1: Region | G1: Peril
A2: Vulnerability - NA SCS Custom | B2: DLM-SCS-US | C2: CVC1 | D2: Chaucer Vulnerability Curve for US Severe Convective Storm
A3: Vulnerability - NA SCS Custom | B3: DLM-SCS-CAN | C3: CVC1 | D3: Chaucer Vulnerability Curve for Canada Severe Convective Storm
A4: Vulnerability Set 101 | B4: DLM-WTS-US | C4: CVC2 | D4: Hartford Vulnerability Curve for US Winterstorm
A5: Custom (NAHU23) - NE/MA SFD | B5: DLM-WS-US | C5: CVC3 | D5: Chubb Vulnerability Curve for US Windstorm
A6: Custom (NAHU23) - NE/MA SFD | B6: DLM-WS-CAN | C6: CVC3 | D6: Chubb Vulnerability Curve for Canada Windstorm
A7: Custom (NAHU23) - NE/MA SFD | B7: DLM-WS-MEX | C7: CVC3 | D7: Chubb Vulnerability Curve for Mexico Windstorm
A8: Custom (NAHU23) - NE/MA SFD + MFD + HTL | B8: DLM-WS-US | C8: CVC3 | D8: Chubb Vulnerability Curve for US Windstorm
A9: Custom (NAHU23) - NE/MA SFD + MFD + HTL | B9: DLM-WS-CAN | C9: CVC3 | D9: Chubb Vulnerability Curve for Canada Windstorm
A10: Custom (NAHU23) - NE/MA SFD + MFD + HTL | B10: DLM-WS-MEX | C10: CVC3 | D10: Chubb Vulnerability Curve for Mexico Windstorm
A11: Custom EUEQ Rupture Length | B11: DLM-EQ-EUR-21 | C11: CRL1 | D11: Generali Custom EUEQ Rupture Length

Sheet Bundles
A1: productcode | B1: productname | C1: Model Type | D1: Model SubType | E1: Data Type | F1: Bundle Region | G1: Bundle Subregion | H1: RI Region | I1: RI Subregions | J1: Peril | K1: Model Type | L1: Model Subtype | M1: Data Type
A2: CATSUITE-GBL | B2: Global Catastrophe Modeling Suite | C2: All | D2: All | F2: Global | G2: Global
A3: CATSUITE-ASIA | B3: Catastrophe Modeling Suite: Asia | C3: All | D3: Bundle | F3: Asia | H3: China,China (RL22),Southeast Asia,India,South Korea,Guam,Japan,Philippines,Taiwan
A4: CATSUITE-ANZ | B4: Catastrophe Modeling Suite: Australia & New Zealand | C4: All | D4: Bundle | F4: Australia New Zealand | H4: Australia,New Zealand
A5: CATSUITE-EUR | B5: Catastrophe Modeling Suite: Europe | C5: All | D5: Bundle | F5: Europe | H5: EU,Europe (Integrated),Israel,United Kingdom
A6: CATSUITE-LAM | B6: Catastrophe Modeling Suite: Latin America | C6: All | D6: Bundle | F6: Latin America | H6: NA,North America,Central America,South America,Caribbean,North Atlantic
A7: CATSUITE-NAM | B7: Catastrophe Modeling Suite: North America | C7: All | D7: Bundle | F7: North America | H7: NA,North America,North Atlantic
A8: CATSUITE-JPN | B8: Catastrophe Modeling Suite: Japan | C8: All | D8: Bundle | G8: Japan | I8: Japan,JP | J8: Earthquake, Windstorm
A9: CATSUITE-AUS | B9: Catastrophe Modeling Suite: Australia | C9: All | D9: Bundle | G9: Australia | I9: Australia,AU
A10: CATSUITE-ITA | B10: Catastrophe Modeling Suite: Italy | C10: All | D10: Bundle | G10: Italy | I10: Italy,IT
A11: CATSUITE-CAN | B11: Catastrophe Modeling Suite: Canada | C11: All | D11: Bundle | G11: Canada | I11: CA,XC,Canada,Nova Scotia,Prince Edward Island,New Brunswick,Newfoundland and Labrador,Ontario,Quebec,Yukon Territory,Northwest Territories,Nunavut,Saskatchewan,Manitoba,Alberta,British Columbia
A12: CATSUITE-CAR | B12: Catastrophe Modeling Suite: Caribbean | C12: All | D12: Bundle | G12: Caribbean | I12: CB,FC,DM,BL,AW,HT,BS,VG,GD,TT,AG,TC,M2,XL,DO,XK,XM,CU,LC,GP,AI,MQ,BM,XJ,BB,KN,PR,VI,MF,JM,XN,K1,VC,Caribbean,Puerto Rico,Dominica,Saint Barthelemy,Aruba,Haiti,Bahamas,British Virgin Islands,Grenada,Trinidad and Tobago,Antigua and Barbuda,Turks and Caicos,Montserrat,Saba,Dominican Republic,St. Eustatius,Curacao,Cuba,Saint Lucia,Guadeloupe,Anguilla,Martinique,Bermuda,Sint Maarten,Barbados,St Kitts and Nevis,Puerto Rico,U.S. Virgin Islands,Saint Martin,Jamaica,Bonaire,Cayman Islands,Saint Vincent and the Grenadines
A13: CATSUITE-CAM | B13: Catastrophe Modeling Suite: Central America | C13: All | D13: Bundle | G13: Central America | I13: BZ,CR,GT,HN,NI,PA,EC,SV,Costa Rica,Belize,Nicaragua,Honduras,Guatemala,El Salvador,Panama,Ecuador
A14: CATSUITE-FRA | B14: Catastrophe Modeling Suite: France | C14: All | D14: Bundle | G14: France | I14: France,FR
A15: CATSUITE-DEU | B15: Catastrophe Modeling Suite: Germany | C15: All | D15: Bundle | G15: Germany | I15: Germany,Offshore Northern Europe,DE
A16: CATSUITE-IND | B16: Catastrophe Modeling Suite: India | C16: All | D16: Bundle | G16: India | I16: India,IN
A17: CATSUITE-MEX | B17: Catastrophe Modeling Suite: Mexico | C17: All | D17: Bundle | G17: Mexico | I17: Mexico,MX
A18: CATSUITE-NZL | B18: Catastrophe Modeling Suite: New Zealand | C18: All | D18: Bundle | G18: New Zealand | I18: New Zealand,NZ
A19: CATSUITE-SAM | B19: Catastrophe Modeling Suite: South America | C19: All | D19: Bundle | G19: South America | I19: Bolivia,Argentina,Brazil,Peru,Venezuela,Colombia,Chile,Ecuador,AR,BO,BR,CL,CO,PE,VE
A20: CATSUITE-SEA | B20: Catastrophe Modeling Suite: Southeast Asia | C20: All | D20: Bundle | G20: Southeast Asia | I20: Indonesia,Singapore,Thailand,Malaysia,Philippines,Vietnam,ID,SG,TH,MY,PH,VN
... A27: CATSUITE-CHE | B27: Catastrophe Modeling Suite: Switzerland | C27: All | D27: Bundle | G27: Switzerland | I27: Switzerland,Liechtenstein,CH,LI
A29: ERDSUITE-GBL | B29: Enhanced Risk Data Suite: Global | E29: All | F29: Global | G29: Global
A30: ERDSUITE-EUR | B30: Enhanced Risk Data Suite: Europe | E30: All | F30: Europe
A31: ERDSUITE-US | B31: Enhanced Risk Data Suite: United States | E31: All | G31: United States
A1048576: ERDSUITE-EUR
